2017-12-04 01:09:12,614 - inciwebLogger - INFO - Key Not Found Incident Description
2017-12-04 01:09:28,974 - inciwebLogger - INFO - Key Not Found Incident Description
2017-12-04 01:09:31,127 - inciwebLogger - INFO - Key Not Found Incident Description
2017-12-04 01:09:36,433 - inciwebLogger - INFO - Key Not Found Incident Description
2017-12-04 01:09:37,170 - inciwebLogger - INFO - Key Not Found Incident Description
2017-12-04 01:09:38,011 - inciwebLogger - INFO - Key Not Found Incident Description
2017-12-04 01:09:39,597 - inciwebLogger - INFO - Key Not Found Incident Description
2017-12-04 01:09:40,208 - inciwebLogger - INFO - Key Not Found Incident Description
2017-12-04 01:09:46,209 - inciwebLogger - INFO - Key Not Found Incident Description
2017-12-04 01:09:46,966 - inciwebLogger - INFO - Key Not Found Incident Description
2017-12-04 01:09:47,612 - inciwebLogger - INFO - Key Not Found Incident Description
2017-12-04 01:09:49,018 - inciwebLogger - INFO - Key Not Found Incident Description
2017-12-04 01:09:49,881 - inciwebLogger - INFO - Key Not Found Incident Description
2017-12-04 01:09:50,690 - inciwebLogger - INFO - Key Not Found Incident Description
2017-12-04 01:09:54,918 - inciwebLogger - INFO - Key Not Found Incident Description
2017-12-04 01:09:56,425 - inciwebLogger - INFO - Key Not Found Incident Description
2017-12-04 01:09:58,729 - inciwebLogger - INFO - Key Not Found Incident Description
2017-12-04 01:09:59,350 - inciwebLogger - INFO - Key Not Found Incident Description
2017-12-04 01:10:09,677 - inciwebLogger - INFO - Key Not Found Incident Description
2017-12-04 01:10:16,166 - inciwebLogger - INFO - Key Not Found Incident Description
2017-12-04 01:10:24,181 - inciwebLogger - INFO - Key Not Found Incident Description
2017-12-04 01:10:26,820 - inciwebLogger - INFO - Key Not Found Incident Description
2017-12-04 01:10:30,267 - inciwebLogger - INFO - Key Not Found Incident Description
2017-12-04 18:00:03,444 - inciwebLogger - INFO - generic exception: Traceback (most recent call last):
  File "/Users/brianmccall/inciweb-scraper/main.py", line 91, in <module>
    page = urllib2.urlopen(link)
  File "/System/Library/Frameworks/Python.framework/Versions/2.7/lib/python2.7/urllib2.py", line 154, in urlopen
    return opener.open(url, data, timeout)
  File "/System/Library/Frameworks/Python.framework/Versions/2.7/lib/python2.7/urllib2.py", line 431, in open
    response = self._open(req, data)
  File "/System/Library/Frameworks/Python.framework/Versions/2.7/lib/python2.7/urllib2.py", line 449, in _open
    '_open', req)
  File "/System/Library/Frameworks/Python.framework/Versions/2.7/lib/python2.7/urllib2.py", line 409, in _call_chain
    result = func(*args)
  File "/System/Library/Frameworks/Python.framework/Versions/2.7/lib/python2.7/urllib2.py", line 1240, in https_open
    context=self._context)
  File "/System/Library/Frameworks/Python.framework/Versions/2.7/lib/python2.7/urllib2.py", line 1200, in do_open
    r = h.getresponse(buffering=True)
  File "/System/Library/Frameworks/Python.framework/Versions/2.7/lib/python2.7/httplib.py", line 1132, in getresponse
    response.begin()
  File "/System/Library/Frameworks/Python.framework/Versions/2.7/lib/python2.7/httplib.py", line 453, in begin
    version, status, reason = self._read_status()
  File "/System/Library/Frameworks/Python.framework/Versions/2.7/lib/python2.7/httplib.py", line 409, in _read_status
    line = self.fp.readline(_MAXLINE + 1)
  File "/System/Library/Frameworks/Python.framework/Versions/2.7/lib/python2.7/socket.py", line 480, in readline
    data = self._sock.recv(self._rbufsize)
  File "/System/Library/Frameworks/Python.framework/Versions/2.7/lib/python2.7/ssl.py", line 734, in recv
    return self.read(buflen)
  File "/System/Library/Frameworks/Python.framework/Versions/2.7/lib/python2.7/ssl.py", line 621, in read
    v = self._sslobj.read(len or 1024)
error: [Errno 54] Connection reset by peer

2017-12-04 18:00:03,965 - inciwebLogger - INFO - generic exception: Traceback (most recent call last):
  File "/Users/brianmccall/inciweb-scraper/main.py", line 91, in <module>
    page = urllib2.urlopen(link)
  File "/System/Library/Frameworks/Python.framework/Versions/2.7/lib/python2.7/urllib2.py", line 154, in urlopen
    return opener.open(url, data, timeout)
  File "/System/Library/Frameworks/Python.framework/Versions/2.7/lib/python2.7/urllib2.py", line 431, in open
    response = self._open(req, data)
  File "/System/Library/Frameworks/Python.framework/Versions/2.7/lib/python2.7/urllib2.py", line 449, in _open
    '_open', req)
  File "/System/Library/Frameworks/Python.framework/Versions/2.7/lib/python2.7/urllib2.py", line 409, in _call_chain
    result = func(*args)
  File "/System/Library/Frameworks/Python.framework/Versions/2.7/lib/python2.7/urllib2.py", line 1240, in https_open
    context=self._context)
  File "/System/Library/Frameworks/Python.framework/Versions/2.7/lib/python2.7/urllib2.py", line 1200, in do_open
    r = h.getresponse(buffering=True)
  File "/System/Library/Frameworks/Python.framework/Versions/2.7/lib/python2.7/httplib.py", line 1132, in getresponse
    response.begin()
  File "/System/Library/Frameworks/Python.framework/Versions/2.7/lib/python2.7/httplib.py", line 453, in begin
    version, status, reason = self._read_status()
  File "/System/Library/Frameworks/Python.framework/Versions/2.7/lib/python2.7/httplib.py", line 409, in _read_status
    line = self.fp.readline(_MAXLINE + 1)
  File "/System/Library/Frameworks/Python.framework/Versions/2.7/lib/python2.7/socket.py", line 480, in readline
    data = self._sock.recv(self._rbufsize)
  File "/System/Library/Frameworks/Python.framework/Versions/2.7/lib/python2.7/ssl.py", line 734, in recv
    return self.read(buflen)
  File "/System/Library/Frameworks/Python.framework/Versions/2.7/lib/python2.7/ssl.py", line 621, in read
    v = self._sslobj.read(len or 1024)
error: [Errno 54] Connection reset by peer

2017-12-04 18:00:04,471 - inciwebLogger - INFO - generic exception: Traceback (most recent call last):
  File "/Users/brianmccall/inciweb-scraper/main.py", line 91, in <module>
    page = urllib2.urlopen(link)
  File "/System/Library/Frameworks/Python.framework/Versions/2.7/lib/python2.7/urllib2.py", line 154, in urlopen
    return opener.open(url, data, timeout)
  File "/System/Library/Frameworks/Python.framework/Versions/2.7/lib/python2.7/urllib2.py", line 431, in open
    response = self._open(req, data)
  File "/System/Library/Frameworks/Python.framework/Versions/2.7/lib/python2.7/urllib2.py", line 449, in _open
    '_open', req)
  File "/System/Library/Frameworks/Python.framework/Versions/2.7/lib/python2.7/urllib2.py", line 409, in _call_chain
    result = func(*args)
  File "/System/Library/Frameworks/Python.framework/Versions/2.7/lib/python2.7/urllib2.py", line 1240, in https_open
    context=self._context)
  File "/System/Library/Frameworks/Python.framework/Versions/2.7/lib/python2.7/urllib2.py", line 1200, in do_open
    r = h.getresponse(buffering=True)
  File "/System/Library/Frameworks/Python.framework/Versions/2.7/lib/python2.7/httplib.py", line 1132, in getresponse
    response.begin()
  File "/System/Library/Frameworks/Python.framework/Versions/2.7/lib/python2.7/httplib.py", line 453, in begin
    version, status, reason = self._read_status()
  File "/System/Library/Frameworks/Python.framework/Versions/2.7/lib/python2.7/httplib.py", line 409, in _read_status
    line = self.fp.readline(_MAXLINE + 1)
  File "/System/Library/Frameworks/Python.framework/Versions/2.7/lib/python2.7/socket.py", line 480, in readline
    data = self._sock.recv(self._rbufsize)
  File "/System/Library/Frameworks/Python.framework/Versions/2.7/lib/python2.7/ssl.py", line 734, in recv
    return self.read(buflen)
  File "/System/Library/Frameworks/Python.framework/Versions/2.7/lib/python2.7/ssl.py", line 621, in read
    v = self._sslobj.read(len or 1024)
error: [Errno 54] Connection reset by peer

2017-12-04 18:00:04,968 - inciwebLogger - INFO - generic exception: Traceback (most recent call last):
  File "/Users/brianmccall/inciweb-scraper/main.py", line 91, in <module>
    page = urllib2.urlopen(link)
  File "/System/Library/Frameworks/Python.framework/Versions/2.7/lib/python2.7/urllib2.py", line 154, in urlopen
    return opener.open(url, data, timeout)
  File "/System/Library/Frameworks/Python.framework/Versions/2.7/lib/python2.7/urllib2.py", line 431, in open
    response = self._open(req, data)
  File "/System/Library/Frameworks/Python.framework/Versions/2.7/lib/python2.7/urllib2.py", line 449, in _open
    '_open', req)
  File "/System/Library/Frameworks/Python.framework/Versions/2.7/lib/python2.7/urllib2.py", line 409, in _call_chain
    result = func(*args)
  File "/System/Library/Frameworks/Python.framework/Versions/2.7/lib/python2.7/urllib2.py", line 1240, in https_open
    context=self._context)
  File "/System/Library/Frameworks/Python.framework/Versions/2.7/lib/python2.7/urllib2.py", line 1200, in do_open
    r = h.getresponse(buffering=True)
  File "/System/Library/Frameworks/Python.framework/Versions/2.7/lib/python2.7/httplib.py", line 1132, in getresponse
    response.begin()
  File "/System/Library/Frameworks/Python.framework/Versions/2.7/lib/python2.7/httplib.py", line 453, in begin
    version, status, reason = self._read_status()
  File "/System/Library/Frameworks/Python.framework/Versions/2.7/lib/python2.7/httplib.py", line 409, in _read_status
    line = self.fp.readline(_MAXLINE + 1)
  File "/System/Library/Frameworks/Python.framework/Versions/2.7/lib/python2.7/socket.py", line 480, in readline
    data = self._sock.recv(self._rbufsize)
  File "/System/Library/Frameworks/Python.framework/Versions/2.7/lib/python2.7/ssl.py", line 734, in recv
    return self.read(buflen)
  File "/System/Library/Frameworks/Python.framework/Versions/2.7/lib/python2.7/ssl.py", line 621, in read
    v = self._sslobj.read(len or 1024)
error: [Errno 54] Connection reset by peer

